[2025-01-19T20:32:15.562+0000] {processor.py:161} INFO - Started process (PID=70) to work on /opt/airflow/dags/insert_data.py
[2025-01-19T20:32:15.579+0000] {processor.py:830} INFO - Processing file /opt/airflow/dags/insert_data.py for tasks to queue
[2025-01-19T20:32:15.622+0000] {logging_mixin.py:188} INFO - [2025-01-19T20:32:15.614+0000] {dagbag.py:538} INFO - Filling up the DagBag from /opt/airflow/dags/insert_data.py
[2025-01-19T20:32:21.104+0000] {logging_mixin.py:188} INFO - [2025-01-19T20:32:21.096+0000] {dagbag.py:348} ERROR - Failed to import: /opt/airflow/dags/insert_data.py
Traceback (most recent call last):
  File "/home/airflow/.local/lib/python3.8/site-packages/airflow/models/dagbag.py", line 344, in parse
    loader.exec_module(new_module)
  File "<frozen importlib._bootstrap_external>", line 843, in exec_module
  File "<frozen importlib._bootstrap>", line 219, in _call_with_frames_removed
  File "/opt/airflow/dags/insert_data.py", line 14, in <module>
    PATH = Variable.get("my_path")
  File "/home/airflow/.local/lib/python3.8/site-packages/airflow/models/variable.py", line 143, in get
    raise KeyError(f"Variable {key} does not exist")
KeyError: 'Variable my_path does not exist'
[2025-01-19T20:32:21.108+0000] {processor.py:842} WARNING - No viable dags retrieved from /opt/airflow/dags/insert_data.py
[2025-01-19T20:32:21.152+0000] {processor.py:183} INFO - Processing /opt/airflow/dags/insert_data.py took 5.640 seconds
[2025-01-19T20:32:51.441+0000] {processor.py:161} INFO - Started process (PID=78) to work on /opt/airflow/dags/insert_data.py
[2025-01-19T20:32:51.443+0000] {processor.py:830} INFO - Processing file /opt/airflow/dags/insert_data.py for tasks to queue
[2025-01-19T20:32:51.451+0000] {logging_mixin.py:188} INFO - [2025-01-19T20:32:51.450+0000] {dagbag.py:538} INFO - Filling up the DagBag from /opt/airflow/dags/insert_data.py
[2025-01-19T20:32:51.968+0000] {logging_mixin.py:188} INFO - [2025-01-19T20:32:51.961+0000] {dagbag.py:348} ERROR - Failed to import: /opt/airflow/dags/insert_data.py
Traceback (most recent call last):
  File "/home/airflow/.local/lib/python3.8/site-packages/airflow/models/dagbag.py", line 344, in parse
    loader.exec_module(new_module)
  File "<frozen importlib._bootstrap_external>", line 843, in exec_module
  File "<frozen importlib._bootstrap>", line 219, in _call_with_frames_removed
  File "/opt/airflow/dags/insert_data.py", line 14, in <module>
    PATH = Variable.get("my_path")
  File "/home/airflow/.local/lib/python3.8/site-packages/airflow/models/variable.py", line 143, in get
    raise KeyError(f"Variable {key} does not exist")
KeyError: 'Variable my_path does not exist'
[2025-01-19T20:32:51.969+0000] {processor.py:842} WARNING - No viable dags retrieved from /opt/airflow/dags/insert_data.py
[2025-01-19T20:32:51.995+0000] {processor.py:183} INFO - Processing /opt/airflow/dags/insert_data.py took 0.566 seconds
[2025-01-19T20:33:22.204+0000] {processor.py:161} INFO - Started process (PID=86) to work on /opt/airflow/dags/insert_data.py
[2025-01-19T20:33:22.206+0000] {processor.py:830} INFO - Processing file /opt/airflow/dags/insert_data.py for tasks to queue
[2025-01-19T20:33:22.208+0000] {logging_mixin.py:188} INFO - [2025-01-19T20:33:22.207+0000] {dagbag.py:538} INFO - Filling up the DagBag from /opt/airflow/dags/insert_data.py
[2025-01-19T20:33:22.533+0000] {logging_mixin.py:188} INFO - [2025-01-19T20:33:22.528+0000] {dagbag.py:348} ERROR - Failed to import: /opt/airflow/dags/insert_data.py
Traceback (most recent call last):
  File "/home/airflow/.local/lib/python3.8/site-packages/airflow/models/dagbag.py", line 344, in parse
    loader.exec_module(new_module)
  File "<frozen importlib._bootstrap_external>", line 843, in exec_module
  File "<frozen importlib._bootstrap>", line 219, in _call_with_frames_removed
  File "/opt/airflow/dags/insert_data.py", line 14, in <module>
    PATH = Variable.get("my_path")
  File "/home/airflow/.local/lib/python3.8/site-packages/airflow/models/variable.py", line 143, in get
    raise KeyError(f"Variable {key} does not exist")
KeyError: 'Variable my_path does not exist'
[2025-01-19T20:33:22.534+0000] {processor.py:842} WARNING - No viable dags retrieved from /opt/airflow/dags/insert_data.py
[2025-01-19T20:33:22.549+0000] {processor.py:183} INFO - Processing /opt/airflow/dags/insert_data.py took 0.347 seconds
[2025-01-19T20:33:52.731+0000] {processor.py:161} INFO - Started process (PID=94) to work on /opt/airflow/dags/insert_data.py
[2025-01-19T20:33:52.732+0000] {processor.py:830} INFO - Processing file /opt/airflow/dags/insert_data.py for tasks to queue
[2025-01-19T20:33:52.735+0000] {logging_mixin.py:188} INFO - [2025-01-19T20:33:52.734+0000] {dagbag.py:538} INFO - Filling up the DagBag from /opt/airflow/dags/insert_data.py
[2025-01-19T20:33:56.260+0000] {logging_mixin.py:188} INFO - [2025-01-19T20:33:56.256+0000] {dagbag.py:348} ERROR - Failed to import: /opt/airflow/dags/insert_data.py
Traceback (most recent call last):
  File "/home/airflow/.local/lib/python3.8/site-packages/airflow/models/dagbag.py", line 344, in parse
    loader.exec_module(new_module)
  File "<frozen importlib._bootstrap_external>", line 843, in exec_module
  File "<frozen importlib._bootstrap>", line 219, in _call_with_frames_removed
  File "/opt/airflow/dags/insert_data.py", line 14, in <module>
    PATH = Variable.get("my_path")
  File "/home/airflow/.local/lib/python3.8/site-packages/airflow/models/variable.py", line 143, in get
    raise KeyError(f"Variable {key} does not exist")
KeyError: 'Variable my_path does not exist'
[2025-01-19T20:33:56.261+0000] {processor.py:842} WARNING - No viable dags retrieved from /opt/airflow/dags/insert_data.py
[2025-01-19T20:33:56.271+0000] {processor.py:183} INFO - Processing /opt/airflow/dags/insert_data.py took 3.544 seconds
[2025-01-19T20:34:26.754+0000] {processor.py:161} INFO - Started process (PID=102) to work on /opt/airflow/dags/insert_data.py
[2025-01-19T20:34:26.756+0000] {processor.py:830} INFO - Processing file /opt/airflow/dags/insert_data.py for tasks to queue
[2025-01-19T20:34:26.761+0000] {logging_mixin.py:188} INFO - [2025-01-19T20:34:26.761+0000] {dagbag.py:538} INFO - Filling up the DagBag from /opt/airflow/dags/insert_data.py
[2025-01-19T20:34:27.545+0000] {logging_mixin.py:188} INFO - [2025-01-19T20:34:27.543+0000] {templater.py:95} ERROR - Failed to resolve template field 'sql'
Traceback (most recent call last):
  File "/home/airflow/.local/lib/python3.8/site-packages/airflow/template/templater.py", line 93, in resolve_template_files
    setattr(self, field, env.loader.get_source(env, content)[0])  # type: ignore
  File "/home/airflow/.local/lib/python3.8/site-packages/jinja2/loaders.py", line 204, in get_source
    raise TemplateNotFound(template)
jinja2.exceptions.TemplateNotFound: sql/fill_dm_account_turnover_f.sql
[2025-01-19T20:34:27.547+0000] {logging_mixin.py:188} INFO - [2025-01-19T20:34:27.547+0000] {templater.py:95} ERROR - Failed to resolve template field 'sql'
Traceback (most recent call last):
  File "/home/airflow/.local/lib/python3.8/site-packages/airflow/template/templater.py", line 93, in resolve_template_files
    setattr(self, field, env.loader.get_source(env, content)[0])  # type: ignore
  File "/home/airflow/.local/lib/python3.8/site-packages/jinja2/loaders.py", line 204, in get_source
    raise TemplateNotFound(template)
jinja2.exceptions.TemplateNotFound: sql/fill_dm_account_balance_f.sql
[2025-01-19T20:34:27.568+0000] {processor.py:840} INFO - DAG(s) 'insert_data' retrieved from /opt/airflow/dags/insert_data.py
[2025-01-19T20:34:27.973+0000] {logging_mixin.py:188} INFO - [2025-01-19T20:34:27.972+0000] {override.py:1769} INFO - Created Permission View: can delete on DAG:insert_data
[2025-01-19T20:34:27.983+0000] {logging_mixin.py:188} INFO - [2025-01-19T20:34:27.983+0000] {override.py:1769} INFO - Created Permission View: can read on DAG:insert_data
[2025-01-19T20:34:27.996+0000] {logging_mixin.py:188} INFO - [2025-01-19T20:34:27.995+0000] {override.py:1769} INFO - Created Permission View: can edit on DAG:insert_data
[2025-01-19T20:34:27.997+0000] {logging_mixin.py:188} INFO - [2025-01-19T20:34:27.996+0000] {dag.py:3036} INFO - Sync 1 DAGs
[2025-01-19T20:34:28.009+0000] {logging_mixin.py:188} INFO - [2025-01-19T20:34:28.009+0000] {dag.py:3058} INFO - Creating ORM DAG for insert_data
[2025-01-19T20:34:28.022+0000] {logging_mixin.py:188} INFO - [2025-01-19T20:34:28.021+0000] {dag.py:3823} INFO - Setting next_dagrun for insert_data to 2025-01-18 00:00:00+00:00, run_after=2025-01-19 00:00:00+00:00
[2025-01-19T20:34:28.044+0000] {processor.py:183} INFO - Processing /opt/airflow/dags/insert_data.py took 1.296 seconds
[2025-01-19T20:34:58.238+0000] {processor.py:161} INFO - Started process (PID=110) to work on /opt/airflow/dags/insert_data.py
[2025-01-19T20:34:58.239+0000] {processor.py:830} INFO - Processing file /opt/airflow/dags/insert_data.py for tasks to queue
[2025-01-19T20:34:58.240+0000] {logging_mixin.py:188} INFO - [2025-01-19T20:34:58.240+0000] {dagbag.py:538} INFO - Filling up the DagBag from /opt/airflow/dags/insert_data.py
[2025-01-19T20:34:58.507+0000] {logging_mixin.py:188} INFO - [2025-01-19T20:34:58.506+0000] {templater.py:95} ERROR - Failed to resolve template field 'sql'
Traceback (most recent call last):
  File "/home/airflow/.local/lib/python3.8/site-packages/airflow/template/templater.py", line 93, in resolve_template_files
    setattr(self, field, env.loader.get_source(env, content)[0])  # type: ignore
  File "/home/airflow/.local/lib/python3.8/site-packages/jinja2/loaders.py", line 204, in get_source
    raise TemplateNotFound(template)
jinja2.exceptions.TemplateNotFound: sql/fill_dm_account_turnover_f.sql
[2025-01-19T20:34:58.508+0000] {logging_mixin.py:188} INFO - [2025-01-19T20:34:58.508+0000] {templater.py:95} ERROR - Failed to resolve template field 'sql'
Traceback (most recent call last):
  File "/home/airflow/.local/lib/python3.8/site-packages/airflow/template/templater.py", line 93, in resolve_template_files
    setattr(self, field, env.loader.get_source(env, content)[0])  # type: ignore
  File "/home/airflow/.local/lib/python3.8/site-packages/jinja2/loaders.py", line 204, in get_source
    raise TemplateNotFound(template)
jinja2.exceptions.TemplateNotFound: sql/fill_dm_account_balance_f.sql
[2025-01-19T20:34:58.511+0000] {processor.py:840} INFO - DAG(s) 'insert_data' retrieved from /opt/airflow/dags/insert_data.py
[2025-01-19T20:34:58.529+0000] {logging_mixin.py:188} INFO - [2025-01-19T20:34:58.529+0000] {dag.py:3036} INFO - Sync 1 DAGs
[2025-01-19T20:34:58.657+0000] {logging_mixin.py:188} INFO - [2025-01-19T20:34:58.657+0000] {dag.py:3823} INFO - Setting next_dagrun for insert_data to 2025-01-18 00:00:00+00:00, run_after=2025-01-19 00:00:00+00:00
[2025-01-19T20:34:58.676+0000] {processor.py:183} INFO - Processing /opt/airflow/dags/insert_data.py took 0.442 seconds
[2025-01-19T20:35:28.902+0000] {processor.py:161} INFO - Started process (PID=118) to work on /opt/airflow/dags/insert_data.py
[2025-01-19T20:35:28.903+0000] {processor.py:830} INFO - Processing file /opt/airflow/dags/insert_data.py for tasks to queue
[2025-01-19T20:35:28.905+0000] {logging_mixin.py:188} INFO - [2025-01-19T20:35:28.904+0000] {dagbag.py:538} INFO - Filling up the DagBag from /opt/airflow/dags/insert_data.py
[2025-01-19T20:35:29.178+0000] {logging_mixin.py:188} INFO - [2025-01-19T20:35:29.177+0000] {templater.py:95} ERROR - Failed to resolve template field 'sql'
Traceback (most recent call last):
  File "/home/airflow/.local/lib/python3.8/site-packages/airflow/template/templater.py", line 93, in resolve_template_files
    setattr(self, field, env.loader.get_source(env, content)[0])  # type: ignore
  File "/home/airflow/.local/lib/python3.8/site-packages/jinja2/loaders.py", line 204, in get_source
    raise TemplateNotFound(template)
jinja2.exceptions.TemplateNotFound: sql/fill_dm_account_turnover_f.sql
[2025-01-19T20:35:29.180+0000] {logging_mixin.py:188} INFO - [2025-01-19T20:35:29.179+0000] {templater.py:95} ERROR - Failed to resolve template field 'sql'
Traceback (most recent call last):
  File "/home/airflow/.local/lib/python3.8/site-packages/airflow/template/templater.py", line 93, in resolve_template_files
    setattr(self, field, env.loader.get_source(env, content)[0])  # type: ignore
  File "/home/airflow/.local/lib/python3.8/site-packages/jinja2/loaders.py", line 204, in get_source
    raise TemplateNotFound(template)
jinja2.exceptions.TemplateNotFound: sql/fill_dm_account_balance_f.sql
[2025-01-19T20:35:29.184+0000] {processor.py:840} INFO - DAG(s) 'insert_data' retrieved from /opt/airflow/dags/insert_data.py
[2025-01-19T20:35:29.371+0000] {logging_mixin.py:188} INFO - [2025-01-19T20:35:29.371+0000] {dag.py:3036} INFO - Sync 1 DAGs
[2025-01-19T20:35:29.397+0000] {logging_mixin.py:188} INFO - [2025-01-19T20:35:29.396+0000] {dag.py:3823} INFO - Setting next_dagrun for insert_data to 2025-01-18 00:00:00+00:00, run_after=2025-01-19 00:00:00+00:00
[2025-01-19T20:35:29.416+0000] {processor.py:183} INFO - Processing /opt/airflow/dags/insert_data.py took 0.517 seconds
[2025-01-19T20:35:59.651+0000] {processor.py:161} INFO - Started process (PID=126) to work on /opt/airflow/dags/insert_data.py
[2025-01-19T20:35:59.652+0000] {processor.py:830} INFO - Processing file /opt/airflow/dags/insert_data.py for tasks to queue
[2025-01-19T20:35:59.654+0000] {logging_mixin.py:188} INFO - [2025-01-19T20:35:59.654+0000] {dagbag.py:538} INFO - Filling up the DagBag from /opt/airflow/dags/insert_data.py
[2025-01-19T20:36:00.630+0000] {logging_mixin.py:188} INFO - [2025-01-19T20:36:00.628+0000] {templater.py:95} ERROR - Failed to resolve template field 'sql'
Traceback (most recent call last):
  File "/home/airflow/.local/lib/python3.8/site-packages/airflow/template/templater.py", line 93, in resolve_template_files
    setattr(self, field, env.loader.get_source(env, content)[0])  # type: ignore
  File "/home/airflow/.local/lib/python3.8/site-packages/jinja2/loaders.py", line 204, in get_source
    raise TemplateNotFound(template)
jinja2.exceptions.TemplateNotFound: sql/fill_dm_account_turnover_f.sql
[2025-01-19T20:36:00.648+0000] {logging_mixin.py:188} INFO - [2025-01-19T20:36:00.647+0000] {templater.py:95} ERROR - Failed to resolve template field 'sql'
Traceback (most recent call last):
  File "/home/airflow/.local/lib/python3.8/site-packages/airflow/template/templater.py", line 93, in resolve_template_files
    setattr(self, field, env.loader.get_source(env, content)[0])  # type: ignore
  File "/home/airflow/.local/lib/python3.8/site-packages/jinja2/loaders.py", line 204, in get_source
    raise TemplateNotFound(template)
jinja2.exceptions.TemplateNotFound: sql/fill_dm_account_balance_f.sql
[2025-01-19T20:36:00.654+0000] {processor.py:840} INFO - DAG(s) 'insert_data' retrieved from /opt/airflow/dags/insert_data.py
[2025-01-19T20:36:00.710+0000] {logging_mixin.py:188} INFO - [2025-01-19T20:36:00.709+0000] {dag.py:3036} INFO - Sync 1 DAGs
[2025-01-19T20:36:00.766+0000] {logging_mixin.py:188} INFO - [2025-01-19T20:36:00.765+0000] {dag.py:3823} INFO - Setting next_dagrun for insert_data to 2025-01-18 00:00:00+00:00, run_after=2025-01-19 00:00:00+00:00
[2025-01-19T20:36:00.887+0000] {processor.py:183} INFO - Processing /opt/airflow/dags/insert_data.py took 1.238 seconds
[2025-01-19T20:36:31.108+0000] {processor.py:161} INFO - Started process (PID=134) to work on /opt/airflow/dags/insert_data.py
[2025-01-19T20:36:31.110+0000] {processor.py:830} INFO - Processing file /opt/airflow/dags/insert_data.py for tasks to queue
[2025-01-19T20:36:31.112+0000] {logging_mixin.py:188} INFO - [2025-01-19T20:36:31.112+0000] {dagbag.py:538} INFO - Filling up the DagBag from /opt/airflow/dags/insert_data.py
[2025-01-19T20:36:31.547+0000] {logging_mixin.py:188} INFO - [2025-01-19T20:36:31.546+0000] {templater.py:95} ERROR - Failed to resolve template field 'sql'
Traceback (most recent call last):
  File "/home/airflow/.local/lib/python3.8/site-packages/airflow/template/templater.py", line 93, in resolve_template_files
    setattr(self, field, env.loader.get_source(env, content)[0])  # type: ignore
  File "/home/airflow/.local/lib/python3.8/site-packages/jinja2/loaders.py", line 204, in get_source
    raise TemplateNotFound(template)
jinja2.exceptions.TemplateNotFound: sql/fill_dm_account_turnover_f.sql
[2025-01-19T20:36:31.547+0000] {logging_mixin.py:188} INFO - [2025-01-19T20:36:31.547+0000] {templater.py:95} ERROR - Failed to resolve template field 'sql'
Traceback (most recent call last):
  File "/home/airflow/.local/lib/python3.8/site-packages/airflow/template/templater.py", line 93, in resolve_template_files
    setattr(self, field, env.loader.get_source(env, content)[0])  # type: ignore
  File "/home/airflow/.local/lib/python3.8/site-packages/jinja2/loaders.py", line 204, in get_source
    raise TemplateNotFound(template)
jinja2.exceptions.TemplateNotFound: sql/fill_dm_account_balance_f.sql
[2025-01-19T20:36:31.550+0000] {processor.py:840} INFO - DAG(s) 'insert_data' retrieved from /opt/airflow/dags/insert_data.py
[2025-01-19T20:36:31.570+0000] {logging_mixin.py:188} INFO - [2025-01-19T20:36:31.570+0000] {dag.py:3036} INFO - Sync 1 DAGs
[2025-01-19T20:36:31.591+0000] {logging_mixin.py:188} INFO - [2025-01-19T20:36:31.591+0000] {dag.py:3823} INFO - Setting next_dagrun for insert_data to 2025-01-18 00:00:00+00:00, run_after=2025-01-19 00:00:00+00:00
[2025-01-19T20:36:31.608+0000] {processor.py:183} INFO - Processing /opt/airflow/dags/insert_data.py took 0.508 seconds
[2025-01-19T20:37:03.733+0000] {processor.py:161} INFO - Started process (PID=151) to work on /opt/airflow/dags/insert_data.py
[2025-01-19T20:37:03.741+0000] {processor.py:830} INFO - Processing file /opt/airflow/dags/insert_data.py for tasks to queue
[2025-01-19T20:37:03.794+0000] {logging_mixin.py:188} INFO - [2025-01-19T20:37:03.788+0000] {dagbag.py:538} INFO - Filling up the DagBag from /opt/airflow/dags/insert_data.py
[2025-01-19T20:37:23.330+0000] {logging_mixin.py:188} INFO - [2025-01-19T20:37:23.327+0000] {templater.py:95} ERROR - Failed to resolve template field 'sql'
Traceback (most recent call last):
  File "/home/airflow/.local/lib/python3.8/site-packages/airflow/template/templater.py", line 93, in resolve_template_files
    setattr(self, field, env.loader.get_source(env, content)[0])  # type: ignore
  File "/home/airflow/.local/lib/python3.8/site-packages/jinja2/loaders.py", line 204, in get_source
    raise TemplateNotFound(template)
jinja2.exceptions.TemplateNotFound: sql/fill_dm_account_turnover_f.sql
[2025-01-19T20:37:23.332+0000] {logging_mixin.py:188} INFO - [2025-01-19T20:37:23.331+0000] {templater.py:95} ERROR - Failed to resolve template field 'sql'
Traceback (most recent call last):
  File "/home/airflow/.local/lib/python3.8/site-packages/airflow/template/templater.py", line 93, in resolve_template_files
    setattr(self, field, env.loader.get_source(env, content)[0])  # type: ignore
  File "/home/airflow/.local/lib/python3.8/site-packages/jinja2/loaders.py", line 204, in get_source
    raise TemplateNotFound(template)
jinja2.exceptions.TemplateNotFound: sql/fill_dm_account_balance_f.sql
[2025-01-19T20:37:23.343+0000] {processor.py:840} INFO - DAG(s) 'insert_data' retrieved from /opt/airflow/dags/insert_data.py
[2025-01-19T20:37:23.372+0000] {logging_mixin.py:188} INFO - [2025-01-19T20:37:23.372+0000] {dag.py:3036} INFO - Sync 1 DAGs
[2025-01-19T20:37:23.403+0000] {logging_mixin.py:188} INFO - [2025-01-19T20:37:23.403+0000] {dag.py:3823} INFO - Setting next_dagrun for insert_data to 2025-01-19 00:00:00+00:00, run_after=2025-01-20 00:00:00+00:00
[2025-01-19T20:37:23.428+0000] {processor.py:183} INFO - Processing /opt/airflow/dags/insert_data.py took 19.735 seconds
[2025-01-19T20:37:53.843+0000] {processor.py:161} INFO - Started process (PID=165) to work on /opt/airflow/dags/insert_data.py
[2025-01-19T20:37:53.848+0000] {processor.py:830} INFO - Processing file /opt/airflow/dags/insert_data.py for tasks to queue
[2025-01-19T20:37:53.869+0000] {logging_mixin.py:188} INFO - [2025-01-19T20:37:53.867+0000] {dagbag.py:538} INFO - Filling up the DagBag from /opt/airflow/dags/insert_data.py
[2025-01-19T20:37:54.506+0000] {logging_mixin.py:188} INFO - [2025-01-19T20:37:54.504+0000] {templater.py:95} ERROR - Failed to resolve template field 'sql'
Traceback (most recent call last):
  File "/home/airflow/.local/lib/python3.8/site-packages/airflow/template/templater.py", line 93, in resolve_template_files
    setattr(self, field, env.loader.get_source(env, content)[0])  # type: ignore
  File "/home/airflow/.local/lib/python3.8/site-packages/jinja2/loaders.py", line 204, in get_source
    raise TemplateNotFound(template)
jinja2.exceptions.TemplateNotFound: sql/fill_dm_account_turnover_f.sql
[2025-01-19T20:37:54.507+0000] {logging_mixin.py:188} INFO - [2025-01-19T20:37:54.507+0000] {templater.py:95} ERROR - Failed to resolve template field 'sql'
Traceback (most recent call last):
  File "/home/airflow/.local/lib/python3.8/site-packages/airflow/template/templater.py", line 93, in resolve_template_files
    setattr(self, field, env.loader.get_source(env, content)[0])  # type: ignore
  File "/home/airflow/.local/lib/python3.8/site-packages/jinja2/loaders.py", line 204, in get_source
    raise TemplateNotFound(template)
jinja2.exceptions.TemplateNotFound: sql/fill_dm_account_balance_f.sql
[2025-01-19T20:37:54.513+0000] {processor.py:840} INFO - DAG(s) 'insert_data' retrieved from /opt/airflow/dags/insert_data.py
[2025-01-19T20:37:54.789+0000] {logging_mixin.py:188} INFO - [2025-01-19T20:37:54.789+0000] {dag.py:3036} INFO - Sync 1 DAGs
[2025-01-19T20:37:54.817+0000] {logging_mixin.py:188} INFO - [2025-01-19T20:37:54.816+0000] {dag.py:3823} INFO - Setting next_dagrun for insert_data to 2025-01-19 00:00:00+00:00, run_after=2025-01-20 00:00:00+00:00
[2025-01-19T20:37:54.847+0000] {processor.py:183} INFO - Processing /opt/airflow/dags/insert_data.py took 1.034 seconds
[2025-01-19T20:38:25.661+0000] {processor.py:161} INFO - Started process (PID=173) to work on /opt/airflow/dags/insert_data.py
[2025-01-19T20:38:25.663+0000] {processor.py:830} INFO - Processing file /opt/airflow/dags/insert_data.py for tasks to queue
[2025-01-19T20:38:25.671+0000] {logging_mixin.py:188} INFO - [2025-01-19T20:38:25.671+0000] {dagbag.py:538} INFO - Filling up the DagBag from /opt/airflow/dags/insert_data.py
[2025-01-19T20:38:26.485+0000] {logging_mixin.py:188} INFO - [2025-01-19T20:38:26.483+0000] {templater.py:95} ERROR - Failed to resolve template field 'sql'
Traceback (most recent call last):
  File "/home/airflow/.local/lib/python3.8/site-packages/airflow/template/templater.py", line 93, in resolve_template_files
    setattr(self, field, env.loader.get_source(env, content)[0])  # type: ignore
  File "/home/airflow/.local/lib/python3.8/site-packages/jinja2/loaders.py", line 204, in get_source
    raise TemplateNotFound(template)
jinja2.exceptions.TemplateNotFound: sql/fill_dm_account_turnover_f.sql
[2025-01-19T20:38:26.489+0000] {logging_mixin.py:188} INFO - [2025-01-19T20:38:26.488+0000] {templater.py:95} ERROR - Failed to resolve template field 'sql'
Traceback (most recent call last):
  File "/home/airflow/.local/lib/python3.8/site-packages/airflow/template/templater.py", line 93, in resolve_template_files
    setattr(self, field, env.loader.get_source(env, content)[0])  # type: ignore
  File "/home/airflow/.local/lib/python3.8/site-packages/jinja2/loaders.py", line 204, in get_source
    raise TemplateNotFound(template)
jinja2.exceptions.TemplateNotFound: sql/fill_dm_account_balance_f.sql
[2025-01-19T20:38:26.496+0000] {processor.py:840} INFO - DAG(s) 'insert_data' retrieved from /opt/airflow/dags/insert_data.py
[2025-01-19T20:38:26.533+0000] {logging_mixin.py:188} INFO - [2025-01-19T20:38:26.532+0000] {dag.py:3036} INFO - Sync 1 DAGs
[2025-01-19T20:38:26.580+0000] {logging_mixin.py:188} INFO - [2025-01-19T20:38:26.579+0000] {dag.py:3823} INFO - Setting next_dagrun for insert_data to 2025-01-19 00:00:00+00:00, run_after=2025-01-20 00:00:00+00:00
[2025-01-19T20:38:26.611+0000] {processor.py:183} INFO - Processing /opt/airflow/dags/insert_data.py took 0.963 seconds
[2025-01-19T20:38:56.887+0000] {processor.py:161} INFO - Started process (PID=181) to work on /opt/airflow/dags/insert_data.py
[2025-01-19T20:38:56.888+0000] {processor.py:830} INFO - Processing file /opt/airflow/dags/insert_data.py for tasks to queue
[2025-01-19T20:38:56.890+0000] {logging_mixin.py:188} INFO - [2025-01-19T20:38:56.889+0000] {dagbag.py:538} INFO - Filling up the DagBag from /opt/airflow/dags/insert_data.py
[2025-01-19T20:38:57.365+0000] {logging_mixin.py:188} INFO - [2025-01-19T20:38:57.364+0000] {templater.py:95} ERROR - Failed to resolve template field 'sql'
Traceback (most recent call last):
  File "/home/airflow/.local/lib/python3.8/site-packages/airflow/template/templater.py", line 93, in resolve_template_files
    setattr(self, field, env.loader.get_source(env, content)[0])  # type: ignore
  File "/home/airflow/.local/lib/python3.8/site-packages/jinja2/loaders.py", line 204, in get_source
    raise TemplateNotFound(template)
jinja2.exceptions.TemplateNotFound: sql/fill_dm_account_turnover_f.sql
[2025-01-19T20:38:57.365+0000] {logging_mixin.py:188} INFO - [2025-01-19T20:38:57.365+0000] {templater.py:95} ERROR - Failed to resolve template field 'sql'
Traceback (most recent call last):
  File "/home/airflow/.local/lib/python3.8/site-packages/airflow/template/templater.py", line 93, in resolve_template_files
    setattr(self, field, env.loader.get_source(env, content)[0])  # type: ignore
  File "/home/airflow/.local/lib/python3.8/site-packages/jinja2/loaders.py", line 204, in get_source
    raise TemplateNotFound(template)
jinja2.exceptions.TemplateNotFound: sql/fill_dm_account_balance_f.sql
[2025-01-19T20:38:57.369+0000] {processor.py:840} INFO - DAG(s) 'insert_data' retrieved from /opt/airflow/dags/insert_data.py
[2025-01-19T20:38:57.390+0000] {logging_mixin.py:188} INFO - [2025-01-19T20:38:57.389+0000] {dag.py:3036} INFO - Sync 1 DAGs
[2025-01-19T20:38:57.419+0000] {logging_mixin.py:188} INFO - [2025-01-19T20:38:57.419+0000] {dag.py:3823} INFO - Setting next_dagrun for insert_data to 2025-01-19 00:00:00+00:00, run_after=2025-01-20 00:00:00+00:00
[2025-01-19T20:38:57.440+0000] {processor.py:183} INFO - Processing /opt/airflow/dags/insert_data.py took 0.557 seconds
[2025-01-19T20:39:27.689+0000] {processor.py:161} INFO - Started process (PID=189) to work on /opt/airflow/dags/insert_data.py
[2025-01-19T20:39:27.690+0000] {processor.py:830} INFO - Processing file /opt/airflow/dags/insert_data.py for tasks to queue
[2025-01-19T20:39:27.692+0000] {logging_mixin.py:188} INFO - [2025-01-19T20:39:27.692+0000] {dagbag.py:538} INFO - Filling up the DagBag from /opt/airflow/dags/insert_data.py
[2025-01-19T20:39:28.281+0000] {logging_mixin.py:188} INFO - [2025-01-19T20:39:28.279+0000] {templater.py:95} ERROR - Failed to resolve template field 'sql'
Traceback (most recent call last):
  File "/home/airflow/.local/lib/python3.8/site-packages/airflow/template/templater.py", line 93, in resolve_template_files
    setattr(self, field, env.loader.get_source(env, content)[0])  # type: ignore
  File "/home/airflow/.local/lib/python3.8/site-packages/jinja2/loaders.py", line 204, in get_source
    raise TemplateNotFound(template)
jinja2.exceptions.TemplateNotFound: sql/fill_dm_account_turnover_f.sql
[2025-01-19T20:39:28.282+0000] {logging_mixin.py:188} INFO - [2025-01-19T20:39:28.282+0000] {templater.py:95} ERROR - Failed to resolve template field 'sql'
Traceback (most recent call last):
  File "/home/airflow/.local/lib/python3.8/site-packages/airflow/template/templater.py", line 93, in resolve_template_files
    setattr(self, field, env.loader.get_source(env, content)[0])  # type: ignore
  File "/home/airflow/.local/lib/python3.8/site-packages/jinja2/loaders.py", line 204, in get_source
    raise TemplateNotFound(template)
jinja2.exceptions.TemplateNotFound: sql/fill_dm_account_balance_f.sql
[2025-01-19T20:39:28.287+0000] {processor.py:840} INFO - DAG(s) 'insert_data' retrieved from /opt/airflow/dags/insert_data.py
[2025-01-19T20:39:28.313+0000] {logging_mixin.py:188} INFO - [2025-01-19T20:39:28.313+0000] {dag.py:3036} INFO - Sync 1 DAGs
[2025-01-19T20:39:28.363+0000] {logging_mixin.py:188} INFO - [2025-01-19T20:39:28.362+0000] {dag.py:3823} INFO - Setting next_dagrun for insert_data to 2025-01-19 00:00:00+00:00, run_after=2025-01-20 00:00:00+00:00
[2025-01-19T20:39:28.404+0000] {processor.py:183} INFO - Processing /opt/airflow/dags/insert_data.py took 0.719 seconds
[2025-01-19T20:39:58.635+0000] {processor.py:161} INFO - Started process (PID=197) to work on /opt/airflow/dags/insert_data.py
[2025-01-19T20:39:58.636+0000] {processor.py:830} INFO - Processing file /opt/airflow/dags/insert_data.py for tasks to queue
[2025-01-19T20:39:58.639+0000] {logging_mixin.py:188} INFO - [2025-01-19T20:39:58.638+0000] {dagbag.py:538} INFO - Filling up the DagBag from /opt/airflow/dags/insert_data.py
[2025-01-19T20:39:59.540+0000] {logging_mixin.py:188} INFO - [2025-01-19T20:39:59.539+0000] {templater.py:95} ERROR - Failed to resolve template field 'sql'
Traceback (most recent call last):
  File "/home/airflow/.local/lib/python3.8/site-packages/airflow/template/templater.py", line 93, in resolve_template_files
    setattr(self, field, env.loader.get_source(env, content)[0])  # type: ignore
  File "/home/airflow/.local/lib/python3.8/site-packages/jinja2/loaders.py", line 204, in get_source
    raise TemplateNotFound(template)
jinja2.exceptions.TemplateNotFound: sql/fill_dm_account_turnover_f.sql
[2025-01-19T20:39:59.541+0000] {logging_mixin.py:188} INFO - [2025-01-19T20:39:59.541+0000] {templater.py:95} ERROR - Failed to resolve template field 'sql'
Traceback (most recent call last):
  File "/home/airflow/.local/lib/python3.8/site-packages/airflow/template/templater.py", line 93, in resolve_template_files
    setattr(self, field, env.loader.get_source(env, content)[0])  # type: ignore
  File "/home/airflow/.local/lib/python3.8/site-packages/jinja2/loaders.py", line 204, in get_source
    raise TemplateNotFound(template)
jinja2.exceptions.TemplateNotFound: sql/fill_dm_account_balance_f.sql
[2025-01-19T20:39:59.544+0000] {processor.py:840} INFO - DAG(s) 'insert_data' retrieved from /opt/airflow/dags/insert_data.py
[2025-01-19T20:39:59.564+0000] {logging_mixin.py:188} INFO - [2025-01-19T20:39:59.563+0000] {dag.py:3036} INFO - Sync 1 DAGs
[2025-01-19T20:39:59.594+0000] {logging_mixin.py:188} INFO - [2025-01-19T20:39:59.594+0000] {dag.py:3823} INFO - Setting next_dagrun for insert_data to 2025-01-19 00:00:00+00:00, run_after=2025-01-20 00:00:00+00:00
[2025-01-19T20:39:59.618+0000] {processor.py:183} INFO - Processing /opt/airflow/dags/insert_data.py took 0.987 seconds
[2025-01-19T20:40:29.865+0000] {processor.py:161} INFO - Started process (PID=205) to work on /opt/airflow/dags/insert_data.py
[2025-01-19T20:40:29.868+0000] {processor.py:830} INFO - Processing file /opt/airflow/dags/insert_data.py for tasks to queue
[2025-01-19T20:40:29.877+0000] {logging_mixin.py:188} INFO - [2025-01-19T20:40:29.877+0000] {dagbag.py:538} INFO - Filling up the DagBag from /opt/airflow/dags/insert_data.py
[2025-01-19T20:40:30.269+0000] {logging_mixin.py:188} INFO - [2025-01-19T20:40:30.269+0000] {templater.py:95} ERROR - Failed to resolve template field 'sql'
Traceback (most recent call last):
  File "/home/airflow/.local/lib/python3.8/site-packages/airflow/template/templater.py", line 93, in resolve_template_files
    setattr(self, field, env.loader.get_source(env, content)[0])  # type: ignore
  File "/home/airflow/.local/lib/python3.8/site-packages/jinja2/loaders.py", line 204, in get_source
    raise TemplateNotFound(template)
jinja2.exceptions.TemplateNotFound: sql/fill_dm_account_turnover_f.sql
[2025-01-19T20:40:30.270+0000] {logging_mixin.py:188} INFO - [2025-01-19T20:40:30.270+0000] {templater.py:95} ERROR - Failed to resolve template field 'sql'
Traceback (most recent call last):
  File "/home/airflow/.local/lib/python3.8/site-packages/airflow/template/templater.py", line 93, in resolve_template_files
    setattr(self, field, env.loader.get_source(env, content)[0])  # type: ignore
  File "/home/airflow/.local/lib/python3.8/site-packages/jinja2/loaders.py", line 204, in get_source
    raise TemplateNotFound(template)
jinja2.exceptions.TemplateNotFound: sql/fill_dm_account_balance_f.sql
[2025-01-19T20:40:30.273+0000] {processor.py:840} INFO - DAG(s) 'insert_data' retrieved from /opt/airflow/dags/insert_data.py
[2025-01-19T20:40:30.437+0000] {logging_mixin.py:188} INFO - [2025-01-19T20:40:30.437+0000] {dag.py:3036} INFO - Sync 1 DAGs
[2025-01-19T20:40:30.457+0000] {logging_mixin.py:188} INFO - [2025-01-19T20:40:30.457+0000] {dag.py:3823} INFO - Setting next_dagrun for insert_data to 2025-01-19 00:00:00+00:00, run_after=2025-01-20 00:00:00+00:00
[2025-01-19T20:40:30.476+0000] {processor.py:183} INFO - Processing /opt/airflow/dags/insert_data.py took 0.616 seconds
[2025-01-19T20:41:00.771+0000] {processor.py:161} INFO - Started process (PID=213) to work on /opt/airflow/dags/insert_data.py
[2025-01-19T20:41:00.774+0000] {processor.py:830} INFO - Processing file /opt/airflow/dags/insert_data.py for tasks to queue
[2025-01-19T20:41:00.786+0000] {logging_mixin.py:188} INFO - [2025-01-19T20:41:00.784+0000] {dagbag.py:538} INFO - Filling up the DagBag from /opt/airflow/dags/insert_data.py
[2025-01-19T20:41:01.334+0000] {logging_mixin.py:188} INFO - [2025-01-19T20:41:01.332+0000] {templater.py:95} ERROR - Failed to resolve template field 'sql'
Traceback (most recent call last):
  File "/home/airflow/.local/lib/python3.8/site-packages/airflow/template/templater.py", line 93, in resolve_template_files
    setattr(self, field, env.loader.get_source(env, content)[0])  # type: ignore
  File "/home/airflow/.local/lib/python3.8/site-packages/jinja2/loaders.py", line 204, in get_source
    raise TemplateNotFound(template)
jinja2.exceptions.TemplateNotFound: sql/fill_dm_account_turnover_f.sql
[2025-01-19T20:41:01.335+0000] {logging_mixin.py:188} INFO - [2025-01-19T20:41:01.335+0000] {templater.py:95} ERROR - Failed to resolve template field 'sql'
Traceback (most recent call last):
  File "/home/airflow/.local/lib/python3.8/site-packages/airflow/template/templater.py", line 93, in resolve_template_files
    setattr(self, field, env.loader.get_source(env, content)[0])  # type: ignore
  File "/home/airflow/.local/lib/python3.8/site-packages/jinja2/loaders.py", line 204, in get_source
    raise TemplateNotFound(template)
jinja2.exceptions.TemplateNotFound: sql/fill_dm_account_balance_f.sql
[2025-01-19T20:41:01.342+0000] {processor.py:840} INFO - DAG(s) 'insert_data' retrieved from /opt/airflow/dags/insert_data.py
[2025-01-19T20:41:02.016+0000] {logging_mixin.py:188} INFO - [2025-01-19T20:41:02.016+0000] {dag.py:3036} INFO - Sync 1 DAGs
[2025-01-19T20:41:02.084+0000] {logging_mixin.py:188} INFO - [2025-01-19T20:41:02.084+0000] {dag.py:3823} INFO - Setting next_dagrun for insert_data to 2025-01-19 00:00:00+00:00, run_after=2025-01-20 00:00:00+00:00
[2025-01-19T20:41:02.131+0000] {processor.py:183} INFO - Processing /opt/airflow/dags/insert_data.py took 1.372 seconds
[2025-01-19T20:41:32.281+0000] {processor.py:161} INFO - Started process (PID=221) to work on /opt/airflow/dags/insert_data.py
[2025-01-19T20:41:32.282+0000] {processor.py:830} INFO - Processing file /opt/airflow/dags/insert_data.py for tasks to queue
[2025-01-19T20:41:32.286+0000] {logging_mixin.py:188} INFO - [2025-01-19T20:41:32.286+0000] {dagbag.py:538} INFO - Filling up the DagBag from /opt/airflow/dags/insert_data.py
[2025-01-19T20:41:32.950+0000] {logging_mixin.py:188} INFO - [2025-01-19T20:41:32.949+0000] {templater.py:95} ERROR - Failed to resolve template field 'sql'
Traceback (most recent call last):
  File "/home/airflow/.local/lib/python3.8/site-packages/airflow/template/templater.py", line 93, in resolve_template_files
    setattr(self, field, env.loader.get_source(env, content)[0])  # type: ignore
  File "/home/airflow/.local/lib/python3.8/site-packages/jinja2/loaders.py", line 204, in get_source
    raise TemplateNotFound(template)
jinja2.exceptions.TemplateNotFound: sql/fill_dm_account_turnover_f.sql
[2025-01-19T20:41:32.951+0000] {logging_mixin.py:188} INFO - [2025-01-19T20:41:32.951+0000] {templater.py:95} ERROR - Failed to resolve template field 'sql'
Traceback (most recent call last):
  File "/home/airflow/.local/lib/python3.8/site-packages/airflow/template/templater.py", line 93, in resolve_template_files
    setattr(self, field, env.loader.get_source(env, content)[0])  # type: ignore
  File "/home/airflow/.local/lib/python3.8/site-packages/jinja2/loaders.py", line 204, in get_source
    raise TemplateNotFound(template)
jinja2.exceptions.TemplateNotFound: sql/fill_dm_account_balance_f.sql
[2025-01-19T20:41:32.955+0000] {processor.py:840} INFO - DAG(s) 'insert_data' retrieved from /opt/airflow/dags/insert_data.py
[2025-01-19T20:41:32.972+0000] {logging_mixin.py:188} INFO - [2025-01-19T20:41:32.972+0000] {dag.py:3036} INFO - Sync 1 DAGs
[2025-01-19T20:41:32.993+0000] {logging_mixin.py:188} INFO - [2025-01-19T20:41:32.993+0000] {dag.py:3823} INFO - Setting next_dagrun for insert_data to 2025-01-19 00:00:00+00:00, run_after=2025-01-20 00:00:00+00:00
[2025-01-19T20:41:33.010+0000] {processor.py:183} INFO - Processing /opt/airflow/dags/insert_data.py took 0.735 seconds
[2025-01-19T20:42:03.287+0000] {processor.py:161} INFO - Started process (PID=229) to work on /opt/airflow/dags/insert_data.py
[2025-01-19T20:42:03.289+0000] {processor.py:830} INFO - Processing file /opt/airflow/dags/insert_data.py for tasks to queue
[2025-01-19T20:42:03.290+0000] {logging_mixin.py:188} INFO - [2025-01-19T20:42:03.290+0000] {dagbag.py:538} INFO - Filling up the DagBag from /opt/airflow/dags/insert_data.py
[2025-01-19T20:42:03.688+0000] {logging_mixin.py:188} INFO - [2025-01-19T20:42:03.687+0000] {templater.py:95} ERROR - Failed to resolve template field 'sql'
Traceback (most recent call last):
  File "/home/airflow/.local/lib/python3.8/site-packages/airflow/template/templater.py", line 93, in resolve_template_files
    setattr(self, field, env.loader.get_source(env, content)[0])  # type: ignore
  File "/home/airflow/.local/lib/python3.8/site-packages/jinja2/loaders.py", line 204, in get_source
    raise TemplateNotFound(template)
jinja2.exceptions.TemplateNotFound: sql/fill_dm_account_turnover_f.sql
[2025-01-19T20:42:03.689+0000] {logging_mixin.py:188} INFO - [2025-01-19T20:42:03.688+0000] {templater.py:95} ERROR - Failed to resolve template field 'sql'
Traceback (most recent call last):
  File "/home/airflow/.local/lib/python3.8/site-packages/airflow/template/templater.py", line 93, in resolve_template_files
    setattr(self, field, env.loader.get_source(env, content)[0])  # type: ignore
  File "/home/airflow/.local/lib/python3.8/site-packages/jinja2/loaders.py", line 204, in get_source
    raise TemplateNotFound(template)
jinja2.exceptions.TemplateNotFound: sql/fill_dm_account_balance_f.sql
[2025-01-19T20:42:03.691+0000] {processor.py:840} INFO - DAG(s) 'insert_data' retrieved from /opt/airflow/dags/insert_data.py
[2025-01-19T20:42:03.707+0000] {logging_mixin.py:188} INFO - [2025-01-19T20:42:03.707+0000] {dag.py:3036} INFO - Sync 1 DAGs
[2025-01-19T20:42:03.725+0000] {logging_mixin.py:188} INFO - [2025-01-19T20:42:03.725+0000] {dag.py:3823} INFO - Setting next_dagrun for insert_data to 2025-01-19 00:00:00+00:00, run_after=2025-01-20 00:00:00+00:00
[2025-01-19T20:42:03.743+0000] {processor.py:183} INFO - Processing /opt/airflow/dags/insert_data.py took 0.459 seconds
[2025-01-19T20:42:33.991+0000] {processor.py:161} INFO - Started process (PID=237) to work on /opt/airflow/dags/insert_data.py
[2025-01-19T20:42:33.992+0000] {processor.py:830} INFO - Processing file /opt/airflow/dags/insert_data.py for tasks to queue
[2025-01-19T20:42:33.994+0000] {logging_mixin.py:188} INFO - [2025-01-19T20:42:33.994+0000] {dagbag.py:538} INFO - Filling up the DagBag from /opt/airflow/dags/insert_data.py
[2025-01-19T20:42:34.364+0000] {logging_mixin.py:188} INFO - [2025-01-19T20:42:34.364+0000] {templater.py:95} ERROR - Failed to resolve template field 'sql'
Traceback (most recent call last):
  File "/home/airflow/.local/lib/python3.8/site-packages/airflow/template/templater.py", line 93, in resolve_template_files
    setattr(self, field, env.loader.get_source(env, content)[0])  # type: ignore
  File "/home/airflow/.local/lib/python3.8/site-packages/jinja2/loaders.py", line 204, in get_source
    raise TemplateNotFound(template)
jinja2.exceptions.TemplateNotFound: sql/fill_dm_account_turnover_f.sql
[2025-01-19T20:42:34.365+0000] {logging_mixin.py:188} INFO - [2025-01-19T20:42:34.365+0000] {templater.py:95} ERROR - Failed to resolve template field 'sql'
Traceback (most recent call last):
  File "/home/airflow/.local/lib/python3.8/site-packages/airflow/template/templater.py", line 93, in resolve_template_files
    setattr(self, field, env.loader.get_source(env, content)[0])  # type: ignore
  File "/home/airflow/.local/lib/python3.8/site-packages/jinja2/loaders.py", line 204, in get_source
    raise TemplateNotFound(template)
jinja2.exceptions.TemplateNotFound: sql/fill_dm_account_balance_f.sql
[2025-01-19T20:42:34.368+0000] {processor.py:840} INFO - DAG(s) 'insert_data' retrieved from /opt/airflow/dags/insert_data.py
[2025-01-19T20:42:34.383+0000] {logging_mixin.py:188} INFO - [2025-01-19T20:42:34.383+0000] {dag.py:3036} INFO - Sync 1 DAGs
[2025-01-19T20:42:34.402+0000] {logging_mixin.py:188} INFO - [2025-01-19T20:42:34.402+0000] {dag.py:3823} INFO - Setting next_dagrun for insert_data to 2025-01-19 00:00:00+00:00, run_after=2025-01-20 00:00:00+00:00
[2025-01-19T20:42:34.419+0000] {processor.py:183} INFO - Processing /opt/airflow/dags/insert_data.py took 0.431 seconds
[2025-01-19T20:43:04.653+0000] {processor.py:161} INFO - Started process (PID=245) to work on /opt/airflow/dags/insert_data.py
[2025-01-19T20:43:04.654+0000] {processor.py:830} INFO - Processing file /opt/airflow/dags/insert_data.py for tasks to queue
[2025-01-19T20:43:04.656+0000] {logging_mixin.py:188} INFO - [2025-01-19T20:43:04.656+0000] {dagbag.py:538} INFO - Filling up the DagBag from /opt/airflow/dags/insert_data.py
[2025-01-19T20:43:05.061+0000] {logging_mixin.py:188} INFO - [2025-01-19T20:43:05.060+0000] {templater.py:95} ERROR - Failed to resolve template field 'sql'
Traceback (most recent call last):
  File "/home/airflow/.local/lib/python3.8/site-packages/airflow/template/templater.py", line 93, in resolve_template_files
    setattr(self, field, env.loader.get_source(env, content)[0])  # type: ignore
  File "/home/airflow/.local/lib/python3.8/site-packages/jinja2/loaders.py", line 204, in get_source
    raise TemplateNotFound(template)
jinja2.exceptions.TemplateNotFound: sql/fill_dm_account_turnover_f.sql
[2025-01-19T20:43:05.062+0000] {logging_mixin.py:188} INFO - [2025-01-19T20:43:05.062+0000] {templater.py:95} ERROR - Failed to resolve template field 'sql'
Traceback (most recent call last):
  File "/home/airflow/.local/lib/python3.8/site-packages/airflow/template/templater.py", line 93, in resolve_template_files
    setattr(self, field, env.loader.get_source(env, content)[0])  # type: ignore
  File "/home/airflow/.local/lib/python3.8/site-packages/jinja2/loaders.py", line 204, in get_source
    raise TemplateNotFound(template)
jinja2.exceptions.TemplateNotFound: sql/fill_dm_account_balance_f.sql
[2025-01-19T20:43:05.066+0000] {processor.py:840} INFO - DAG(s) 'insert_data' retrieved from /opt/airflow/dags/insert_data.py
[2025-01-19T20:43:05.085+0000] {logging_mixin.py:188} INFO - [2025-01-19T20:43:05.084+0000] {dag.py:3036} INFO - Sync 1 DAGs
[2025-01-19T20:43:05.107+0000] {logging_mixin.py:188} INFO - [2025-01-19T20:43:05.107+0000] {dag.py:3823} INFO - Setting next_dagrun for insert_data to 2025-01-19 00:00:00+00:00, run_after=2025-01-20 00:00:00+00:00
[2025-01-19T20:43:05.125+0000] {processor.py:183} INFO - Processing /opt/airflow/dags/insert_data.py took 0.475 seconds
